Workbook
Name ImpactIndicateur: #REF!

Sheet °C | espace | équipe | groupe
A1: tCo2e | C1: 11 | D1: 2 | F1: 0 | G1: 42 | J1: EOD | L1: 45505 | Q1: Baisse température possible max
B2: Nb | C2: Before | D2: After | E2: Max economy | F2: Real economy | G2: Température
A3: ALL | B3: =SUM(B6:B8) -> 240 | C3: =SUM(C6:C8) -> 2640 | D3: =SUM(D6:D8) -> 480 | E3: =SUM(E6:E8) -> 438.90027 | F3: =SUM(F6:F8) -> 53.31695 | G3: =(C3-F3)*$G$1/$C3 -> 41.151776 | Q3: =(C3-E3)*$G$1/$C3 -> 35.017496
A5: Equipe | B5: Nb Enfants | C5: tCO2 France | D5: tCO2e objectif | E5: tCO2e max espace | F5: tCO2e à date | G5: °C | H5: Eco-tCO2e | I5: Moy /espace (tCO2e) | K5: Débloqué Sn-1 | L5: Débloqué Sn | M5: N° | N5: EOD | Q5: Terre-momètre | R5: 46009 | S5: =R5+14 -> 46023 | T5: 45665 | U5: 45673 | V5: 45678 | W5: 45694 | X5: 45706 | Y5: 45714 | Z5: 45729 | AA5: 45743 | AB5: 45385 | AC5: 45763 | AD5: 45781 | AE5: 45791 | AF5: 45437 | AG5: 45446 | AH5: 45457 | AI5: 45112 | AJ5: 45160
A6: Neyron | B6: =Neyron!B3 -> 53 | C6: =B6*$C$1 -> 583 | D6: =B6*$D$1 -> 106 | E6: {=INDIRECT(CELL("contenu",A6)&"!D9")} -> 146.30009 | F6: {=INDIRECT(CELL("contenu",A6)&"!$b$8")} -> 35.89 | G6: =IF(ISERROR((C6-F6)*$G$1/$C6),0,(C6-F6)*$G$1/$C6) -> 39.414443 | H6: =(($C6*$G$1)-(G6*$C6))/$G$1 -> 35.89 | I6: =IF(ISERROR(F6/B6),0,F6/B6) -> 0.67716981 | K6: Requin | L6: {=INDIRECT(CELL("contenu",A6)&"!$d$1")} -> Requin | M6: {=INDIRECT(CELL("contenu",A6)&"!$b$1")} -> 8 | N6: {=INDIRECT(CELL("contenu",A6)&"!$b$18")} -> 12 | P6: Mer | Q6: =A6 -> Neyron | R6: 41.712029 | S6: 41.645214 | T6: 41.527852 | U6: 41.403127 | V6: 41.33272 | W6: 41.047757 | X6: 40.868154 | Y6: 40.800433 | Z6: 40.660231 | AA6: 40.46153 | AB6: 40.331878 | AC6: 40.147681 | AD6: 40.007967 | AE6: 39.849168 | AF6: 39.745982 | AG6: 39.642127 | AL6: =Q6 -> Neyron
A7: Balan | B7: =Balan!B3 -> 96 | C7: =B7*$C$1 -> 1056 | D7: =B7*$D$1 -> 192 | E7: {=INDIRECT(CELL("contenu",A7)&"!D9")} -> 146.30009 | F7: {=INDIRECT(CELL("contenu",A7)&"!$b$8")} -> 13.12354 | G7: =IF(ISERROR((C7-F7)*$G$1/$C7),0,(C7-F7)*$G$1/$C7) -> 41.478041 | H7: =(($C7*$G$1)-(G7*$C7))/$G$1 -> 13.12354 | I7: =IF(ISERROR(F7/B7),0,F7/B7) -> 0.13670354 | K7: Poisson | L7: {=INDIRECT(CELL("contenu",A7)&"!$d$1")} -> Poisson | M7: {=INDIRECT(CELL("contenu",A7)&"!$b$1")} -> 6 | N7: {=INDIRECT(CELL("contenu",A7)&"!$b$18")} -> 2 | P7: Soleil | Q7: =A7 -> Balan | R7: 41.991073 | S7: 41.987075 | T7: 41.984578 | U7: 41.953536 | V7: 41.919473 | W7: 41.847001 | X7: 41.78042 | Y7: 41.753263 | Z7: 41.710588 | AA7: 41.65316 | AB7: 41.620846 | AC7: 41.58703 | AD7: 41.557062 | AE7: 41.545302 | AF7: 41.529749 | AG7: 41.51321 | AL7: =Q7 -> Balan
A8: Sosanimaux | B8: =Sosanimaux!B3 -> 91 | C8: =B8*$C$1 -> 1001 | D8: =B8*$D$1 -> 182 | E8: {=INDIRECT(CELL("contenu",A8)&"!D9")} -> 146.30009 | F8: {=INDIRECT(CELL("contenu",A8)&"!$b$8")} -> 4.3034107 | G8: =IF(ISERROR((C8-F8)*$G$1/$C8),0,(C8-F8)*$G$1/$C8) -> 41.819437 | H8: =((($C8*$G$1)-(G8*$C8))/$G$1) -> 4.3034107 | I8: =IF(ISERROR(F8/B8),0,F8/B8) -> 0.047290228 | K8: Éléphant | L8: {=INDIRECT(CELL("contenu",A8)&"!$d$1")} -> Poisson | M8: {=INDIRECT(CELL("contenu",A8)&"!$b$1")} -> 6 | N8: {=INDIRECT(CELL("contenu",A8)&"!$b$18")} -> 0 | P8: Etoile | Q8: =A8 -> Sosanimaux | R8: 42 | S8: 42 | T8: 42 | U8: 42 | V8: 42 | W8: 42 | X8: 42 | Y8: 42 | Z8: 42 | AA8: 42 | AB8: 42 | AC8: 41.964508 | AD8: 41.942556 | AE8: 41.915418 | AF8: 41.896984 | AG8: 41.872044 | AL8: =Q8 -> Sosanimaux
A9: Sosvegetaux | B9: =Sosvegetaux!B3 -> 81 | C9: =B9*$C$1 -> 891 | D9: =B9*$D$1 -> 162 | E9: {=INDIRECT(CELL("contenu",A9)&"!D9")} -> 146.30009 | F9: {=INDIRECT(CELL("contenu",A9)&"!$b$8")} -> 1.2408034 | G9: =IF(ISERROR((C9-F9)*$G$1/$C9),0,(C9-F9)*$G$1/$C9) -> 41.941511 | H9: =((($C9*$G$1)-(G9*$C9))/$G$1) -> 1.2408034 | I9: =IF(ISERROR(F9/B9),0,F9/B9) -> 0.01531856 | K9: Ours | L9: {=INDIRECT(CELL("contenu",A9)&"!$d$1")} -> Ours | M9: {=INDIRECT(CELL("contenu",A9)&"!$b$1")} -> 4 | N9: {=INDIRECT(CELL("contenu",A9)&"!$b$18")} -> 0 | Q9: =A9 -> Sosvegetaux | R9: 42 | S9: 42 | T9: 42 | U9: 42 | V9: 42 | W9: 42 | X9: 42 | Y9: 42 | Z9: 42 | AA9: 42 | AB9: 42 | AC9: 41.987739 | AD9: 41.977084 | AE9: 41.968855 | AF9: 41.958253 | AG9: 41.953204 | AL9: =Q9 -> Sosvegetaux
A10: Mansart | B10: =Mansart!B3 -> 87 | C10: =B10*$C$1 -> 957 | D10: =B10*$D$1 -> 174 | E10: {=INDIRECT(CELL("contenu",A10)&"!D9")} -> 146.30009 | F10: {=INDIRECT(CELL("contenu",A10)&"!$b$8")} -> 1.6738696 | G10: =IF(ISERROR((C10-F10)*$G$1/$C10),0,(C10-F10)*$G$1/$C10) -> 41.926539 | H10: =((($C10*$G$1)-(G10*$C10))/$G$1) -> 1.6738696 | I10: =IF(ISERROR(F10/B10),0,F10/B10) -> 0.019239881 | K10: Éléphant | L10: {=INDIRECT(CELL("contenu",A10)&"!$d$1")} -> Éléphant | M10: {=INDIRECT(CELL("contenu",A10)&"!$b$1")} -> 5 | N10: {=INDIRECT(CELL("contenu",A10)&"!$b$18")} -> 0 | Q10: =A10 -> Mansart | R10: 42 | S10: 42 | T10: 41.999128 | U10: 41.995423 | V10: 41.992073 | W10: 41.980801 | X10: 41.971166 | Y10: 41.967468 | Z10: 41.961949 | AA10: 41.955829 | AB10: 41.952037 | AC10: 41.947402 | AD10: 41.943896 | AE10: 41.939605 | AF10: 41.936153 | AG10: 41.932608 | AL10: =Q10 -> Mansart
A11: Bronature | B11: =Bronature!B3 -> 50 | C11: =B11*$C$1 -> 550 | D11: =B11*$D$1 -> 100 | E11: {=INDIRECT(CELL("contenu",A11)&"!D9")} -> 146.30009 | F11: {=INDIRECT(CELL("contenu",A11)&"!$b$8")} -> 2.863052 | G11: =IF(ISERROR((C11-F11)*$G$1/$C11),0,(C11-F11)*$G$1/$C11) -> 41.781367 | H11: =((($C11*$G$1)-(G11*$C11))/$G$1) -> 2.863052 | I11: =IF(ISERROR(F11/B11),0,F11/B11) -> 0.05726104 | K11: Poisson | L11: {=INDIRECT(CELL("contenu",A11)&"!$d$1")} -> Poisson | M11: {=INDIRECT(CELL("contenu",A11)&"!$b$1")} -> 6 | N11: {=INDIRECT(CELL("contenu",A11)&"!$b$18")} -> 1 | Q11: =A11 -> Bronature | R11: 42 | S11: 42 | T11: 41.998006 | U11: 41.986444 | V11: 41.972364 | W11: 41.936438 | X11: 41.916802 | Y11: 41.91006 | Z11: 41.896531 | AA11: 41.877823 | AB11: 41.87277 | AC11: 41.851337 | AD11: 41.838592 | AE11: 41.829865 | AF11: 41.819126 | AG11: 41.806133 | AL11: =Q11 -> Bronature
B12: =SUM(B6:B11) -> 458 | G12: =AVERAGE(G6:G11) -> 41.393556 | R12: {=SUM(R$6:R$11/COUNTA(R$6:R$11))} -> 41.950517 | S12: {=SUM(S$6:S$11/COUNTA(S$6:S$11))} -> 41.938715 | T12: {=SUM(T$6:T$11/COUNTA(T$6:T$11))} -> 41.91826 | U12: {=SUM(U$6:U$11/COUNTA(U$6:U$11))} -> 41.889755 | V12: {=SUM(V$6:V$11/COUNTA(V$6:V$11))} -> 41.869438 | W12: {=SUM(W$6:W$11/COUNTA(W$6:W$11))} -> 41.802 | X12: {=SUM(X$6:X$11/COUNTA(X$6:X$11))} -> 41.75609 | Y12: 41.738537 | Z12: 41.704883 | AA12: 41.658057 | AB12: 41.629588 | AC12: 41.58095 | AD12: 41.544526 | AE12: 41.508036 | AF12: 41.481041 | AG12: 41.453221
Q14: Economie kgCO2e | R14: =R5 -> 46009 | S14: =S5 -> 46023 | T14: =T5 -> 45665 | U14: =U5 -> 45673 | V14: =V5 -> 45678 | W14: =W5 -> 45694 | X14: =X5 -> 45706 | Y14: =Y5 -> 45714 | ... AJ14: =AJ5 -> 45160
B15: All | Q15: =Q6 -> Neyron | R15: 3.3969798 | S15: 4.9247677 | T15: 6.5538689 | U15: 8.2851588 | V15: 9.2624752 | W15: 13.218034 | X15: 15.7111 | Y15: 16.651126 | Z15: 18.597263 | AA15: 21.355431 | AB15: 23.15512 | AC15: 25.711958 | AD15: 27.651312 | AE15: 29.855597 | AF15: 31.287916 | AG15: 32.729525 | AL15: =Q15 -> Neyron
A16: Eco. gaz à effet de serre | B16: =SUM(Neyron!B8,Balan!B8,Bronature!B8,Mansart!B8,Sosanimaux!B8,Sosvegetaux!B8) -> 59.094675 | C16: tCO2e | Q16: =Q7 -> Balan | R16: 0.22444812 | S16: 0.324979 | T16: 0.3877643 | U16: 1.1682284 | V16: 2.0246837 | W16: 3.8468395 | X16: 5.5208581 | Y16: 6.2036683 | Z16: 7.2766551 | AA16: 8.7205582 | AB16: 9.5330173 | AC16: 10.383252 | AD16: 11.136723 | AE16: 11.432412 | AF16: 11.823445 | AG16: 12.239298 | AL16: =Q16 -> Balan
A17: Eco. Eau | B17: =SUM(Neyron!B10,Balan!B10,Bronature!B10,Mansart!B10,Sosanimaux!B10,Sosvegetaux!B10)/1000 -> 853.38821 | C17: m3 | Q17: =Q8 -> Sosanimaux | R17: 0 | S17: 0 | T17: 0 | U17: 0 | V17: 0 | W17: 0 | X17: 0 | Y17: 0 | Z17: 0 | AA17: 0 | AB17: 0 | AC17: 0.84589591 | AD17: 1.3690794 | AE17: 2.0158689 | AF17: 2.455211 | AG17: 3.0496176 | AL17: =Q17 -> Sosanimaux
A18: Eco. Déchets | B18: =SUM(Neyron!B12,Balan!B12,Bronature!B12,Mansart!B12,Sosanimaux!B12,Sosvegetaux!B12)/1000 -> 61.812232 | C18: tonnes | H18: Et vous avez aussi fait reculer le jour du dépassement de 2 jours. Cela veut dire que si tout le monde faisait comme vous, les ressources de la planète serait consommées plus tard que l'année dernière. Un grand pas pour la planète ! | Q18: =Q9 -> Sosvegetaux | R18: 0 | S18: 0 | T18: 0 | U18: 0 | V18: 0 | W18: 0 | X18: 0 | Y18: 0 | Z18: 0 | AA18: 0 | AB18: 0 | AC18: 0.26010503 | AD18: 0.4861444 | AE18: 0.66071616 | AF18: 0.88562472 | AG18: 0.99274114
Q19: =Q10 -> Mansart | R19: 0 | S19: 0 | T19: 0.019649247 | U19: 0.10309145 | V19: 0.18062624 | W19: 0.43745575 | X19: 0.65699309 | Y19: 0.74126657 | Z19: 0.86701595 | AA19: 1.0064681 | AB19: 1.0928653 | AC19: 1.1984746 | AD19: 1.2783809 | AE19: 1.3761356 | AF19: 1.4548052 | AG19: 1.535586
Q20: =Q11 -> Bronature | R20: 0 | S20: 0 | T20: 0.026114454 | U20: 0.1775239 | V20: 0.36189374 | W20: 0.83235606 | X20: 1.0895008 | Y20: 1.1777914 | Z20: 1.3549556 | AA20: 1.5999399 | AB20: 1.6661129 | AC20: 1.9467715 | AD20: 2.1136816 | AE20: 2.2279558 | AF20: 2.3685854 | AG20: 2.538728
B21: Moy./enfant | Q21: S | R21: =SUM(R15:R17) -> 3.6214279 | S21: =SUM(S15:S17) -> 5.2497467 | T21: =SUM(T15:T17) -> 6.9416332 | U21: =SUM(U15:U17) -> 9.4533873 | V21: =SUM(V15:V17) -> 11.287159 | W21: =SUM(W15:W17) -> 17.064874 | X21: =SUM(X15:X17) -> 21.231958 | Y21: =SUM(Y15:Y17) -> 22.854795 | ... AH21: =SUM(AH15:AH17) -> 0
A22: Eco. gaz à effet de serre | B22: =B16/$B$3*1000 -> 246.22781 | C22: kgCO2e
A23: Eco. Eau | B23: =B17/$B$3*1000 -> 3555.7842 | C23: Litres | Q23: Economie kgCO2e (moy. par joueur) | R23: =R14 -> 46009 | S23: =S14 -> 46023 | T23: =T14 -> 45665 | U23: =U14 -> 45673 | V23: =V14 -> 45678 | W23: =W14 -> 45694 | X23: =X14 -> 45706 | Y23: =Y14 -> 45714 | ... AJ23: =AJ14 -> 45160
A24: Eco. Déchets | B24: =B18/$B$3*1000 -> 257.55097 | C24: kg | Q24: =Q15 -> Neyron | R24: =R15/$B6 -> 0.064093958
Q25: =Q16 -> Balan | R25: =R16/$B7 -> 0.0023380013
A26: DEBLOCAGE ANIMAUX | Q26: =Q17 -> Sosanimaux | R26: =R17/$B8 -> 0
A27: 0 | B27: Pas de déblocage | Q27: S | R27: =SUM(R24:R26) -> 0.066431959
A28: 1 | B28: =UPPER("é")&"cureuil" -> Écureuil
A29: 2 | B29: Loup | Q29: Economie kgCO2e (prorata joueurs) | R29: =R23 -> 46009 | S29: =S23 -> 46023 | T29: =T23 -> 45665 | U29: =U23 -> 45673 | V29: =V23 -> 45678 | W29: =W23 -> 45694 | X29: =X23 -> 45706 | Y29: =Y23 -> 45714 | ... AJ29: =AJ23 -> 45160
A30: 3 | B30: Lion | Q30: =Q24 -> Neyron | R30: =(R24/R$27)*R$21 -> 3.4939756
A31: 4 | B31: Ours | Q31: =Q25 -> Balan | R31: =(R25/R$27)*R$21 -> 0.12745225
A32: 5 | B32: =UPPER("é")&"léphant" -> Éléphant | Q32: =Q26 -> Sosanimaux | R32: =(R26/R$27)*R$21 -> 0
A33: 6 | B33: Poisson | Q33: S
A34: 7 | B34: Thon
A35: 8 | B35: Requin
A36: 9 | B36: Baleine

Sheet Balan
A1: =UPPER("Déblocage Animaux") -> DÉBLOCAGE ANIMAUX | B1: ='[1]Déblocage animaux'!$J$3 -> 6 | C1: (automatique) | D1: =VLOOKUP(B1,'°C | espace | équipe | groupe'!A28:B36,2) -> Poisson | E1: +1 pour la fin | I1: {=UPPER(RIGHT(CELL("filename",A1),LEN(CELL("filename",A1))-SEARCH("]",CELL("filename",A1))))} -> BALAN
A2: NB semaines pour débloquer le | B2: =[1]Actions!$B$22 -> 6.7833838 | D2: =VLOOKUP(B1+1,'°C | espace | équipe | groupe'!A28:B36,2) -> Thon
A3: =UPPER("Nombre de joueurs") -> NOMBRE DE JOUEURS | B3: {=[1]!Nb_Joueur} -> 96 | C3: (automatique)
A5: =UPPER("Impact à Saisir dans l'administration") -> IMPACT À SAISIR DANS L'ADMINISTRATION | C5: (Dev automatisation en cours)
A6: Bravotitre
A7: Bravotext
A8: Scoreglobal | B8: =[1]Actions!$B$25 -> 13.12354 | C8: tCO2e
A9: Maxscoreglobal | B9: ='[1]Déblocage animaux'!$L$7 -> 27.366616 | C9: tCO2e | D9: 146.30009
A10: Scorewater | B10: =[1]Actions!$B$26 -> 162513.4 | C10: Litres
A11: Maxscorewater | B11: =[1]Actions!$B$12 -> 158966.4 | C11: Litres
A12: Scorepollution | B12: =[1]Actions!$B$27 -> 10081.742 | C12: Kg
A13: Maxscorepollution | B13: =[1]Actions!$B$13 -> 110557.99 | C13: Kg
A14: Depassementnombreplanetes | B14: =[1]Actions!$B$31 -> 1.7339949
A15: Jourdepassementavec | B15: =B16+B18 -> 45507 | C15: =[1]Actions!$B$30 -> 45872.497
A16: Jourdepassementsans | B16: ='°C | espace | équipe | groupe'!L1 -> 45505
A18: Nb Jours gagnés /l'an dernier | B18: =FLOOR(C15-B16,1)- '[1]Synthèse Impact & EOD'!$R$3 -> 2

Sheet Bronature
A1: =UPPER("Déblocage Animaux") -> DÉBLOCAGE ANIMAUX | B1: ='[2]Déblocage animaux'!$J$3 -> 6 | C1: (automatique) | D1: =VLOOKUP(B1,'°C | espace | équipe | groupe'!A28:B36,2) -> Poisson | E1: +2 pour la fin | I1: {=UPPER(RIGHT(CELL("filename",A1),LEN(CELL("filename",A1))-SEARCH("]",CELL("filename",A1))))} -> BRONATURE
A2: NB semaines pour débloquer le | B2: 2,37 | D2: =VLOOKUP(B1+1,'°C | espace | équipe | groupe'!A28:B36,2) -> Thon
A3: =UPPER("Nombre de joueurs") -> NOMBRE DE JOUEURS | B3: {=[2]!Nb_Joueur} -> 50 | C3: (automatique)
A5: =UPPER("Impact à Saisir dans l'administration") -> IMPACT À SAISIR DANS L'ADMINISTRATION | C5: (Dev automatisation en cours)
A6: Bravotitre
A7: Bravotext
A8: Scoreglobal | B8: =[2]Actions!$B$25 -> 2.863052 | C8: tCO2e
A9: Maxscoreglobal | B9: ='[2]Déblocage animaux'!$L$7 -> 5.847079 | C9: tCO2e | D9: 146.30009
A10: Scorewater | B10: =[2]Actions!$B$26 -> 89968.2 | C10: Litres
A11: Maxscorewater | B11: =[2]Actions!$B$12 -> 480480 | C11: Litres
A12: Scorepollution | B12: =[2]Actions!$B$27 -> 1634.53 | C12: Kg
A13: Maxscorepollution | B13: =[2]Actions!$B$13 -> 403 | C13: Kg
A14: Depassementnombreplanetes | B14: =[2]Actions!$B$31 -> 1.7456776
A15: Jourdepassementavec | B15: =B16+B18 -> 45506 | C15: =[2]Actions!$B$30 -> 45871.088
A16: Jourdepassementsans | B16: ='°C | espace | équipe | groupe'!L1 -> 45505
A18: Nb Jours gagnés /l'an dernier | B18: =FLOOR(C15-B16,1)-'[2]Synthèse Impact & EOD'!$R$3 -> 1

Sheet Mansart
A1: =UPPER("Déblocage Animaux") -> DÉBLOCAGE ANIMAUX | B1: ='[3]Déblocage animaux'!$J$3 -> 5 | C1: (automatique) | D1: =VLOOKUP(B1,'°C | espace | équipe | groupe'!A28:B36,2) -> Éléphant | E1: +1 pour la fin | I1: {=UPPER(RIGHT(CELL("filename",A1),LEN(CELL("filename",A1))-SEARCH("]",CELL("filename",A1))))} -> MANSART
A2: NB semaines pour débloquer le | B2: =[3]Actions!$B$22 -> 4.6845214 | D2: =VLOOKUP(B1+1,'°C | espace | équipe | groupe'!A28:B36,2) -> Poisson
A3: =UPPER("Nombre de joueurs") -> NOMBRE DE JOUEURS | B3: {=[3]!Nb_Joueur} -> 87 | C3: (automatique)
A5: =UPPER("Impact à Saisir dans l'administration") -> IMPACT À SAISIR DANS L'ADMINISTRATION | C5: (Dev automatisation en cours)
A6: Bravotitre
A7: Bravotext
A8: Scoreglobal | B8: =[3]Actions!$B$25 -> 1.6738696 | C8: tCO2e
A9: Maxscoreglobal | B9: ='[3]Déblocage animaux'!$L$7 -> 4.3400796 | C9: tCO2e | D9: 146.30009
A10: Scorewater | B10: =[3]Actions!$B$26 -> 18074.006 | C10: Litres
A11: Maxscorewater | B11: =[3]Actions!$B$12 -> 171007.2 | C11: Litres
A12: Scorepollution | B12: =[3]Actions!$B$27 -> 3530.5323 | C12: Kg
A13: Maxscorepollution | B13: =[3]Actions!$B$13 -> 17327.79 | C13: Kg
A14: Depassementnombreplanetes | B14: =[3]Actions!$B$31 -> 1.7540916
A15: Jourdepassementavec | B15: =B16+B18 -> 45505 | C15: =[3]Actions!$B$30 -> 45870.085
A16: Jourdepassementsans | B16: ='°C | espace | équipe | groupe'!L1 -> 45505
A18: Nb Jours gagnés /l'an dernier | B18: =FLOOR(C15-B16,1)-'[3]Synthèse Impact & EOD'!$R$3 -> 0

Sheet Neyron
A1: =UPPER("Déblocage Animaux") -> DÉBLOCAGE ANIMAUX | B1: ='[4]Déblocage animaux'!$J$3 -> 8 | C1: (automatique) | D1: =VLOOKUP(B1,'°C | espace | équipe | groupe'!A28:B36,2) -> Requin | I1: {=UPPER(RIGHT(CELL("filename",A1),LEN(CELL("filename",A1))-SEARCH("]",CELL("filename",A1))))} -> NEYRON
A2: NB semaines pour débloquer le | B2: =[4]Actions!$B$22 -> 1.6641606 | D2: =VLOOKUP(B1+1,'°C | espace | équipe | groupe'!A28:B36,2) -> Baleine
A3: =UPPER("Nombre de joueurs") -> NOMBRE DE JOUEURS | B3: {=[4]!Nb_Joueur} -> 53 | C3: (automatique)
A5: =UPPER("Impact à Saisir dans l'administration") -> IMPACT À SAISIR DANS L'ADMINISTRATION | C5: (Dev automatisation en cours)
A6: Bravotitre
A7: Bravotext
A8: Scoreglobal | B8: =[4]Actions!$B$25 -> 35.89 | C8: tCO2e
A9: Maxscoreglobal | C9: tCO2e | D9: 146.30009
A10: Scorewater | B10: =[4]Actions!$B$26 -> 389713.1 | C10: Litres
A11: Maxscorewater | C11: Litres
A12: Scorepollution | B12: =[4]Actions!$B$27 -> 37360.71 | C12: Kg
A13: Maxscorepollution | C13: Kg
A14: Depassementnombreplanetes | B14: =[4]Actions!$B$31 -> 1.65
A15: Jourdepassementavec | B15: =B16+B18 -> 45517 | C15: =[4]Actions!$B$30 -> 45882.069
A16: Jourdepassementsans | B16: ='°C | espace | équipe | groupe'!L1 -> 45505
A18: Nb Jours gagnés /l'an dernier | B18: =FLOOR(C15-B16,1)-'[4]Synthèse Impact & EOD'!$R$3 -> 12

Sheet Sosanimaux
A1: =UPPER("Déblocage Animaux") -> DÉBLOCAGE ANIMAUX | B1: ='[5]Déblocage animaux'!$J$3 -> 6 | C1: (automatique) | D1: =VLOOKUP(B1,'°C | espace | équipe | groupe'!A28:B36,2) -> Poisson | E1: +1 pour la fin | I1: {=UPPER(RIGHT(CELL("filename",A1),LEN(CELL("filename",A1))-SEARCH("]",CELL("filename",A1))))} -> SOSANIMAUX
A2: NB semaines pour débloquer le | B2: =[5]Actions!$B$22 -> 2.9305974 | D2: =VLOOKUP(B1+1,'°C | espace | équipe | groupe'!A28:B36,2) -> Thon
A3: =UPPER("Nombre de joueurs") -> NOMBRE DE JOUEURS | B3: {=[5]!Nb_Joueur} -> 91 | C3: (automatique)
A5: =UPPER("Impact à Saisir dans l'administration") -> IMPACT À SAISIR DANS L'ADMINISTRATION | C5: (Dev automatisation en cours)
A6: Bravotitre
A7: Bravotext
A8: Scoreglobal | B8: =[5]Actions!$B$25 -> 4.3034107 | C8: tCO2e
A9: Maxscoreglobal | C9: tCO2e | D9: 146.30009
A10: Scorewater | B10: =[5]Actions!$B$26 -> 153481.1 | C10: Litres
A11: Maxscorewater | C11: Litres
A12: Scorepollution | B12: =[5]Actions!$B$27 -> 7120.8588 | C12: Kg
A13: Maxscorepollution | C13: Kg
A14: Depassementnombreplanetes | B14: =[5]Actions!$B$31 -> 1.7471439
A15: Jourdepassementavec | B15: =B16+B18 -> 45505 | C15: =[5]Actions!$B$30 -> 45870.912
A16: Jourdepassementsans | B16: ='°C | espace | équipe | groupe'!L1 -> 45505
A18: Nb Jours gagnés /l'an dernier | B18: =FLOOR(C15-B16,1)-'[5]Synthèse Impact & EOD'!$R$3 -> 0

Sheet Sosvegetaux
A1: =UPPER("Déblocage Animaux") -> DÉBLOCAGE ANIMAUX | B1: ='[6]Déblocage animaux'!$J$3 -> 4 | C1: (automatique) | D1: =VLOOKUP(B1,'°C | espace | équipe | groupe'!A28:B36,2) -> Ours | E1: +1 pour la fin | I1: {=UPPER(RIGHT(CELL("filename",A1),LEN(CELL("filename",A1))-SEARCH("]",CELL("filename",A1))))} -> SOSVEGETAUX
A2: NB semaines pour débloquer le | B2: =[6]Actions!$B$22 -> 1.4895005 | D2: =VLOOKUP(B1+1,'°C | espace | équipe | groupe'!A28:B36,2) -> Éléphant
A3: =UPPER("Nombre de joueurs") -> NOMBRE DE JOUEURS | B3: {=[6]!Nb_Joueur} -> 81 | C3: (automatique)
A5: =UPPER("Impact à Saisir dans l'administration") -> IMPACT À SAISIR DANS L'ADMINISTRATION | C5: (Dev automatisation en cours)
A6: Bravotitre
A7: Bravotext
A8: Scoreglobal | B8: =[6]Actions!$B$25 -> 1.2408034 | C8: tCO2e
A9: Maxscoreglobal | C9: tCO2e | D9: 146.30009
A10: Scorewater | B10: =[6]Actions!$B$26 -> 39638.401 | C10: Litres
A11: Maxscorewater | C11: Litres
A12: Scorepollution | B12: =[6]Actions!$B$27 -> 2083.8597 | C12: Kg
A13: Maxscorepollution | C13: Kg
A14: Depassementnombreplanetes | B14: =[6]Actions!$B$31 -> 1.7518456
A15: Jourdepassementavec | B15: =[6]Actions!$B$30 -> 45870.352 | C15: =[6]Actions!$B$30 -> 45870.352
A16: Jourdepassementsans | B16: ='°C | espace | équipe | groupe'!L1 -> 45505
A18: Nb Jours gagnés /l'an dernier | B18: =FLOOR(C15-B16,1)-'[6]Synthèse Impact & EOD'!$R$3 -> 0

Sheet Bravo texte générique
C7: BRAVO les enfants ! Vous avez réussi à débloquer tous ensemble le LION. Cela signifie que toutes ces petites actions que vous effectuez chaque jour ont permis d'économiser 4.2 tCO2e et que si tout le monde faisait comme vous, le jour du dépassement arriverait 7 jours plus tard que l'année dernière. Un grand pas pour la planète ! Pour aller plus loin, trouvez de nouvelles actions encore impactantes. Un indice : que pouvons-nous changer dans notre alimentation ? Vous pouvez aussi voir le Terre-momètre des toutes les écoles qui jouent en cliquant ici A vous de jouer!!!

Sheet GES par pays par hab
E1: tCO2e
C2: Rang | D2: Pays | E2: 2017
C3: 1 | D3: Qatar | E3: 30,36
C4: 2 | D4: Curaçao | E4: 23,28
C5: 3 | D5: Koweït | E5: 21,61
C6: 4 | D6: Émirats arabes unis | E6: 20,91
C7: 5 | D7: Gibraltar | E7: 20,70
C8: 6 | D8: Bahreïn | E8: 19,97
C9: 7 | D9: Arabie saoudite | E9: 16,16
C10: 8 | D10: Bahreïn | E10: 15,64
C11: 9 | D11: Australie | E11: 15,63
C12: 10 | D12: Canada | E12: 14,99
C13: 11 | D13: États-Unis | E13: 14,61
C14: 12 | D14: Luxembourg | E14: 14,51
... C146: 144 | D146: République démocratique du Congo | E146: 0,03
C147: - | D147: Union soviétique
C148: - | D148: Yougoslavie

Sheet Empreinte eco mondiale
B1: Rang | C1: Pays | D1: Empreinte écologique (hag/hab) | E1: Biocapacité (hag/hab) | F1: Excédent ou déficit écologique (hag/hab) | G1: Population (en millions) | H1: Excédent ou déficit de biocapacité totale (millions hag) | I1: Population (en millions) si biocapacité = empreinte écologique*
B2: 1 | C2: Luxembourg | D2: 15,82 | E2: 1,68 | F2: −14,14 | G2: 0,52 | H2: −7,35 | I2: 0,055221
B3: 2 | C3: Aruba | D3: 11,88 | E3: 0,57 | F3: −11,31 | G3: 0,1 | H3: −1,13 | I3: 0,004798
B4: 3 | C4: Qatar | D4: 10,8 | E4: 1,24 | F4: −9,56 | G4: 2,05 | H4: −19,60 | I4: 0,23537
B5: 4 | C5: Australie | D5: 9,31 | E5: 16,57 | F5: 7,26 | G5: 23,05 | H5: 167,34 | I5: 41,02454
B6: 5 | C6: États-Unis | D6: 8,22 | E6: 3,76 | F6: −4,46 | G6: 317,5 | H6: −1416,05 | I6: 145,2311
B7: 6 | C7: Canada | D7: 8,17 | E7: 16,01 | F7: 7,83 | G7: 34,84 | H7: 272,80 | I7: 68,27275
B8: 7 | C8: Koweït | D8: 8,13 | E8: 0,55 | F8: −7,58 | G8: 3,25 | H8: −24,64 | I8: 0,219865
B9: 8 | C9: Singapour | D9: 7,97 | E9: 0,05 | F9: −7,92 | G9: 5,3 | H9: −41,98 | I9: 0,03325
B10: 9 | C10: Royaume-Uni | D10: 7,93 | E10: 0,56 | F10: −7,37 | G10: 65,648 | H10: −483,83 | I10: 4,635924
B11: 10 | C11: Trinité-et-Tobago | D11: 7,92 | E11: 1,56 | F11: −6,36 | G11: 1,34 | H11: −8,52 | I11: 0,263939
B12: 11 | C12: Montserrat | D12: 7,78 | E12: 1,36 | F12: −6,42 | G12: 0,005 | H12: −0,03 | I12: 0,000874
B13: 12 | C13: Oman | D13: 7,52 | E13: 1,92 | F13: −5,6 | G13: 3,31 | H13: −18,54 | I13: 0,845106
... B26: 24 | C26: Slovénie | D26: 5,81 | E26: 2,35 | F26: −3,47 | G26: 2,07 | H26: −7,18 | I26: 0,837263
B27: 25 | C27: Suisse | D27: 5,79 | E27: 1,3 | F27: −4,48 | G27: 8 | H27: −35,84 | I27: 1,7962
B28: 26 | C28: Bermudes | D28: 5,77 | E28: 0,13 | F28: −5,64 | G28: 0,06 | H28: −0,34 | I28: 0,001352
B29: 27 | C29: Corée du Sud | D29: 5,69 | E29: 0,68 | F29: −5,01 | G29: 49 | H29: −245,49 | I29: 5,855888
B30: 28 | C30: Russie | D30: 5,69 | E30: 6,79 | F30: 1,1 | G30: 143,17 | H30: 157,49 | I30: 170,8479
B31: 29 | C31: Îles Caïmans | D31: 5,65 | E31: 0,32 | F31: −5,33 | G31: 0,06 | H31: −0,32 | I31: 0,003398
B32: 30 | C32: Arabie saoudite | D32: 5,61 | E32: 0,5 | F32: −5,12 | G32: 28,29 | H32: −144,84 | I32: 2,52139
B33: 31 | C33: Nouvelle-Zélande | D33: 5,6 | E33: 10,14 | F33: 4,54 | G33: 4,46 | H33: 20,25 | I33: 8,075786
B34: 32 | C34: Irlande | D34: 5,57 | E34: 3,73 | F34: −1,83 | G34: 4,58 | H34: −8,38 | I34: 3,067038
B35: 33 | C35: Kazakhstan | D35: 5,55 | E35: 3,41 | F35: −2,14 | G35: 16,27 | H35: −34,82 | I35: 9,996523
B36: 34 | C36: Danemark | D36: 5,51 | E36: 4,78 | F36: −0,73 | G36: 5,6 | H36: −4,09 | I36: 4,858076
B37: 35 | C37: Turkménistan | D37: 5,47 | E37: 2,79 | F37: −2,68 | G37: 5,17 | H37: −13,86 | I37: 2,636984
B38: 36 | C38: Antigua-et-Barbuda | D38: 5,38 | E38: 0,94 | F38: −4,44 | G38: 0,09 | H38: −0,40 | I38: 0,015725
B39: 37 | C39: Allemagne | D39: 5,3 | E39: 2,27 | F39: −3,02 | G39: 82,8 | H39: −250,06 | I39: 35,4634
B40: 38 | C40: Pays-Bas | D40: 5,28 | E40: 1,17 | F40: −4,11 | G40: 16,71 | H40: −68,68 | I40: 3,702784
B41: 39 | C41: Tchéquie | D41: 5,19 | E41: 2,46 | F41: −2,73 | G41: 10,66 | H41: −29,10 | I41: 5,052717
... B63: 61 | C63: Liban | D63: 3,84 | E63: 0,33 | F63: −3,51 | G63: 4,65 | H63: −16,32 | I63: 0,399609
B64: 62 | C64: Botswana | D64: 3,83 | E64: 3,47 | F64: −0,35 | G64: 2 | H64: −0,70 | I64: 1,81201
B65: 63 | C65: Monténégro | D65: 3,78 | E65: 3,24 | F65: −0,54 | G65: 0,62 | H65: −0,33 | I65: 0,531429
B66: 64 | C66: Malaisie | D66: 3,71 | E66: 2,41 | F66: −1,3 | G66: 29,24 | H66: −38,01 | I66: 18,99418
B67: 65 | C67: Libye | D67: 3,69 | E67: 0,7 | F67: −3 | G67: 6,16 | H67: −18,48 | I67: 1,168564
B68: 66 | C68: Espagne | D68: 3,67 | E68: 1,25 | F68: −2,42 | G68: 46,76 | H68: −113,16 | I68: 15,92643
B69: 67 | C69: La Réunion | D69: 3,65 | E69: 0,18 | F69: −3,47 | G69: 0,86 | H69: −2,98 | I69: 0,042411
B70: 68 | C70: Nouvelle-Calédonie | D70: 3,58 | E70: 7,67 | F70: 4,09 | G70: 0,25 | H70: 1,02 | I70: 0,535615
B71: 69 | C71: Venezuela | D71: 3,57 | E71: 2,78 | F71: −0,79 | G71: 29,96 | H71: −23,67 | I71: 23,3302
B72: 70 | C72: Maurice | D72: 3,46 | E72: 0,71 | F72: −2,75 | G72: 1,24 | H72: −3,41 | I72: 0,254451
B73: 71 | C73: Chine | D73: 3,38 | E73: 0,94 | F73: −2,44 | G73: 1408,04 | H73: −3435,62 | I73: 391,5851
...
